Workbook

Sheet README
A1: Last Updated: May 01, 2026 04:35 AM | B1: 2026-06-23 11:45 EDT
A2: Total Deals in RFP Data: 652
A3: Total Awards: 81
A4: Source: HubSpot CRM (live pull)
A5: Agency State: sourced from associated Company object agency_state property
A6: Total Records: | B6: 775

Sheet Summary
A1: CAPS RFP DASHBOARD - SUMMARY
A2: Last Refreshed: April 23, 2026
A4: OVERVIEW METRICS
A5: Total RFPs | B5: =COUNTA('RFP Data'!A2:A687)
A6: RFPs with Amount | B6: =COUNTA('RFP Data'!L2:L687)
A7: Total Pipeline Value | B7: =SUM('RFP Data'!L2:L687)
A8: Average Deal Size | B8: =IF(B6>0,B7/B6,0)
A10: INTERVIEW METRICS
A11: Total Deals with Interviews | B11: =COUNTIF('RFP Data'!H2:H687,"Yes") | D11: Subcategory: Interview | E11: =COUNTIF('RFP Data'!I2:I687,"Interview")
A12: Interview Rate (of Total) | B12: =IF(B5>0,B11/B5,0) | D12: Subcategory: BAFO | E12: =COUNTIF('RFP Data'!I2:I687,"BAFO")
A14: AWARD TIMELINE METRICS
A15: Deals with Intent to Award Date | B15: =COUNTA('RFP Data'!S2:S687) | D15: Intent to Award Value ($) | E15: =SUMPRODUCT(('RFP Data'!S2:S687<>"")*1,'RFP Data'!L2:L687)
A16: Deals with Tentatively Awarded Date | B16: =COUNTA('RFP Data'!T2:T687)
A17: Deals with Awarded Date | B17: =COUNTA('RFP Data'!U2:U687) | D17: Awarded Value ($) | E17: =SUMPRODUCT(('RFP Data'!U2:U687<>"")*1,'RFP Data'!L2:L687)
A20: BY STAGE
A21: Stage | B21: Count | D21: Stage | E21: Total Value ($)
A22: Submitted | B22: =COUNTIF('RFP Data'!G2:G687,A22) | D22: Submitted | E22: =SUMIF('RFP Data'!G2:G687,D22,'RFP Data'!L2:L687)
A23: Interview | B23: =COUNTIF('RFP Data'!G2:G687,A23) | D23: Interview | E23: =SUMIF('RFP Data'!G2:G687,D23,'RFP Data'!L2:L687)
A24: Intent to Award | B24: =COUNTIF('RFP Data'!G2:G687,A24) | D24: Intent to Award | E24: =SUMIF('RFP Data'!G2:G687,D24,'RFP Data'!L2:L687)
A25: Closed Won | B25: =COUNTIF('RFP Data'!G2:G687,A25) | D25: Closed Won | E25: =SUMIF('RFP Data'!G2:G687,D25,'RFP Data'!L2:L687)
A26: Closed Lost | B26: =COUNTIF('RFP Data'!G2:G687,A26) | D26: Closed Lost | E26: =SUMIF('RFP Data'!G2:G687,D26,'RFP Data'!L2:L687)
A27: Terminated | B27: =COUNTIF('RFP Data'!G2:G687,A27) | D27: Terminated | E27: =SUMIF('RFP Data'!G2:G687,D27,'RFP Data'!L2:L687)
A28: RFx Cancelled | B28: =COUNTIF('RFP Data'!G2:G687,A28) | D28: RFx Cancelled | E28: =SUMIF('RFP Data'!G2:G687,D28,'RFP Data'!L2:L687)
A31: BY OWNER
A32: Owner | B32: Count | D32: Owner | E32: Total Value ($)
A33: Ashutosh Chauhan | B33: =COUNTIF('RFP Data'!O2:O687,A33) | D33: Ashutosh Chauhan | E33: =SUMIF('RFP Data'!O2:O687,D33,'RFP Data'!L2:L687)
A34: Jyothsna Nanda kishore | B34: =COUNTIF('RFP Data'!O2:O687,A34) | D34: Jyothsna Nanda kishore | E34: =SUMIF('RFP Data'!O2:O687,D34,'RFP Data'!L2:L687)
A35: Abhishek Zalani | B35: =COUNTIF('RFP Data'!O2:O687,A35) | D35: Abhishek Zalani | E35: =SUMIF('RFP Data'!O2:O687,D35,'RFP Data'!L2:L687)
A36: Savya Atrey | B36: =COUNTIF('RFP Data'!O2:O687,A36) | D36: Savya Atrey | E36: =SUMIF('RFP Data'!O2:O687,D36,'RFP Data'!L2:L687)
A37: Madhav Mitruka | B37: =COUNTIF('RFP Data'!O2:O687,A37) | D37: Madhav Mitruka | E37: =SUMIF('RFP Data'!O2:O687,D37,'RFP Data'!L2:L687)
A38: Arshdeep Kaur | B38: =COUNTIF('RFP Data'!O2:O687,A38) | D38: Arshdeep Kaur | E38: =SUMIF('RFP Data'!O2:O687,D38,'RFP Data'!L2:L687)
A39: Vinay Srinivasan | B39: =COUNTIF('RFP Data'!O2:O687,A39) | D39: Vinay Srinivasan | E39: =SUMIF('RFP Data'!O2:O687,D39,'RFP Data'!L2:L687)
A40: Ritoban Maitra | B40: =COUNTIF('RFP Data'!O2:O687,A40) | D40: Ritoban Maitra | E40: =SUMIF('RFP Data'!O2:O687,D40,'RFP Data'!L2:L687)
A41: Ashley Lamaniya | B41: =COUNTIF('RFP Data'!O2:O687,A41) | D41: Ashley Lamaniya | E41: =SUMIF('RFP Data'!O2:O687,D41,'RFP Data'!L2:L687)
A42: Hrithik Srivastava | B42: =COUNTIF('RFP Data'!O2:O687,A42) | D42: Hrithik Srivastava | E42: =SUMIF('RFP Data'!O2:O687,D42,'RFP Data'!L2:L687)
A45: BY SERVICE CATEGORY
A46: Category | B46: Count | D46: Category | E46: Total Value ($)
A47: Managed Services (MSP) | B47: =COUNTIF('RFP Data'!M2:M687,"*"&A47&"*") | D47: Managed Services (MSP) | E47: =SUMIF('RFP Data'!M2:M687,"*"&D47&"*",'RFP Data'!L2:L687)
A48: Consulting | B48: =COUNTIF('RFP Data'!M2:M687,"*"&A48&"*") | D48: Consulting | E48: =SUMIF('RFP Data'!M2:M687,"*"&D48&"*",'RFP Data'!L2:L687)
A49: Platform Implementation (ERP, CRMs) | B49: =COUNTIF('RFP Data'!M2:M687,"*"&A49&"*") | D49: Platform Implementation (ERP, CRMs) | E49: =SUMIF('RFP Data'!M2:M687,"*"&D49&"*",'RFP Data'!L2:L687)
...

Sheet Stage Legend
A1: Stage | B1: Description | C1: HubSpot Internal ID
A2: Submitted | B2: Bid has been submitted and is awaiting review | C2: presentationscheduled
A3: Interview | B3: Shortlisted for interview / BAFO stage | C3: 1620129473
A4: Intent to Award | B4: Agency has indicated intent to award | C4: 2485737153
A5: Closed Won | B5: Deal has been won | C5: closedwon
A6: Closed Lost | B6: Deal has been lost | C6: closedlost
A7: Terminated | B7: RFP process was terminated by the agency | C7: 2203296493
A8: RFx Cancelled | B8: RFP was cancelled before completion | C8: 2766010076
A11: Interview Subcategories
A12: Interview | B12: Standard interview — presentation, Q&A, demo
A13: BAFO | B13: Best and Final Offer — revised/final proposal requested
A15: Award Timeline
A16: Intent to Award Date | B16: Agency communicates intent to award — not yet official
A17: Tentatively Awarded Date | B17: Tentative/conditional award — may be subject to protest period
A18: Awarded Date | B18: Formal award — contract execution can begin

Sheet RFP Data
A1: S.No. | B1: HubSpot ID | C1: RFP Number | D1: Deal Name | E1: Agency | F1: Agency State | G1: Stage | H1: Interview Flag | I1: Interview Subcategory | J1: Bid Closing Date | K1: Submission Date | L1: Amount ($) | M1: Service Category | N1: Submission Mode | O1: Owner | P1: Interview Type | Q1: Interview Date | R1: BAFO Date | S1: Intent to Award Date | T1: Tentatively Awarded Date | U1: Awarded Date | V1: Award Status | W1: Won Reason | X1: Lost Reason | Y1: Created Date | Z1: HubSpot Link | AA1: Delivery Required
A2: 1 | B2: 180942918364 | D2: CITY WEBSITE REPLACEMENT PLATFORM | E2: City of Englewood | F2: Colorado | G2: Closed Lost | H2: No | J2: 45938 | K2: 45680 | M2: Modernization / Migration | O2: Madhav Mitruka | Y2: 2025-10-08 | Z2: https://app.hubspot.com/contacts/243046792/record/0-3/180942918364
A3: 2 | B3: 235860602564 | C3: RFQ-AR-1398 | D3: Metropolitan Water District of Southern California - On-Call Information Technology Cybersecurity Services | E3: Metropolitan Water District of Southern California | F3: California | G3: Closed Won | H3: No | J3: 45999 | K3: 45771 | M3: Managed Services (MSP) | N3: Portal | O3: Madhav Mitruka | S3: 2025-12-02 | U3: 45993 | Y3: 2025-12-08 | Z3: https://app.hubspot.com/contacts/243046792/record/0-3/235860602564
A4: 3 | B4: 127482765035 | C4: RFP NO. NC- 2025-14 | D4: Fresno County Superintendent of Schools - Computer Maintenance & Technology Support Services | E4: FRESNO COUNTY SUPERINTENDENT OF SCHOOLS | F4: California | G4: Closed Won | H4: No | J4: 45796 | K4: 45796 | L4: 500000 | M4: Consulting;Support & Maintenance | N4: Email | O4: Arshdeep Kaur | S4: 2025-06-13 | U4: 45968 | V4: In Process | Y4: 2025-07-23 | Z4: https://app.hubspot.com/contacts/243046792/record/0-3/127482765035 | AA4: No
A5: 4 | B5: 127743477490 | D5: EPIC 6- RFP 21.25 Technology Solutions & Services | E5: Region 6 Education Service Center | F5: Texas | G5: Closed Won | H5: No | J5: 46142 | K5: 45807 | M5: Staff Augmentation | N5: Portal | O5: Jyothsna Nanda kishore | S5: 2025-06-16 | U5: 45831 | Y5: 2025-07-23 | Z5: https://app.hubspot.com/contacts/243046792/record/0-3/127743477490 | AA5: No
A6: 5 | B6: 175110048474 | D6: Commonwealth of Pennsylvania - Agile ITQ Development | E6: Commonwealth of Pennsylvania | F6: Pennsylvania | G6: Closed Won | H6: No | J6: 45932 | K6: 45832 | M6: Staff Augmentation | N6: Portal | O6: Madhav Mitruka | S6: 2025-10-02 | U6: 45932 | Y6: 2025-10-02 | Z6: https://app.hubspot.com/contacts/243046792/record/0-3/175110048474 | AA6: No
A7: 6 | B7: 106496879328 | C7: 928 | D7: Cybersecurity & Information Security Services | G7: Closed Lost | H7: No | J7: 46112 | K7: 45834 | O7: Madhav Mitruka | Y7: 2025-06-25 | Z7: https://app.hubspot.com/contacts/243046792/record/0-3/106496879328
A8: 7 | B8: 121105638127 | C8: 25-0212-IT | D8: MICROSOFT OFFICE 365, EXCHANGE,DEFENDER, TRAINING AND TECH SUPPORT | E8: City of Florissant | F8: Missouri | G8: Closed Lost | H8: No | J8: 46113 | K8: 45835 | M8: Consulting | O8: Jyothsna Nanda kishore | V8: In Process | Y8: 2025-07-17 | Z8: https://app.hubspot.com/contacts/243046792/record/0-3/121105638127 | AA8: Yes
A9: 8 | B9: 110969525953 | C9: NA | D9: Managed IT Services - Lucas County | E9: Lucas County Board of Developmental Disabilities | F9: Ohio | G9: Closed Lost | H9: No | J9: 46113 | K9: 45841 | L9: 381250 | M9: Managed Services (MSP) | N9: Portal | O9: Jyothsna Nanda kishore | Y9: 2025-07-02 | Z9: https://app.hubspot.com/contacts/243046792/record/0-3/110969525953
A10: 9 | B10: 135153706705 | C10: RFQ1762822 | D10: Implementation of Electronic Filing (eFiling) | E10: U.S. Consumer Product Safety Commission (CPSC) | F10: Washington, D.C. | G10: Closed Lost | H10: No | J10: 46106 | K10: 45845 | M10: Platform Implementation (ERP, CRMs) | O10: Jyothsna Nanda kishore | Y10: 2025-07-31 | Z10: https://app.hubspot.com/contacts/243046792/record/0-3/135153706705
A11: 10 | B11: 119087249139 | D11: Enterprise Private Cloud Disaster Recovery Services | E11: Contra Costa County | F11: California | G11: Closed Lost | H11: Yes | I11: Interview | J11: 46146 | K11: 45848 | L11: 290000 | M11: Consulting | N11: Email | O11: Jyothsna Nanda kishore | P11: Interview Scheduled | Q11: 2025-09-18 | Y11: 2025-07-11 | Z11: https://app.hubspot.com/contacts/243046792/record/0-3/119087249139
A12: 11 | B12: 118951637707 | C12: RFP_F_0000000055 | D12: CRM ROADMAP: DISCOVERY & PHASE 1 IMPLEMTATION | E12: University of Colorado | F12: Colorado | G12: Closed Lost | H12: No | J12: 45975 | K12: 45852 | L12: 254000 | O12: Jyothsna Nanda kishore | Y12: 2025-07-11 | Z12: https://app.hubspot.com/contacts/243046792/record/0-3/118951637707
A13: 12 | B13: 110968805088 | C13: C001203 | D13: Senior Java Architect | E13: New York State Office of the State Comptroller | F13: New York | G13: Closed Lost | H13: No | J13: 46113 | K13: 45854 | M13: Staff Augmentation | N13: Email | O13: Jyothsna Nanda kishore | Y13: 2025-07-02 | Z13: https://app.hubspot.com/contacts/243046792/record/0-3/110968805088
A14: 13 | B14: 110968874738 | C14: 2025-019 | D14: (ERP) Tyler Software Configuration & Customization Services- QSL | G14: Closed Lost | H14: No | J14: 45937 | K14: 45859 | N14: Portal | O14: Madhav Mitruka | Y14: 2025-07-03 | Z14: https://app.hubspot.com/contacts/243046792/record/0-3/110968874738
A15: 14 | B15: 110712028891 | D15: Oregon League of Cities - STAFFING SERVICES WITH RELATED SERVICES AND SOLUTIONS | E15: Oregon League of Cities | F15: Oregon | G15: Closed Won | H15: No | J15: 46007 | K15: 45859 | M15: Staff Augmentation | N15: Portal | O15: Madhav Mitruka | S15: 2025-12-15 | U15: 46066 | Y15: 2025-07-01 | Z15: https://app.hubspot.com/contacts/243046792/record/0-3/110712028891 | AA15: Yes
A16: 15 | B16: 110968803016 | C16: RFQ-0011580-TECH-2025 | D16: Power Platform/Azure Fabric Launch RFQ | G16: Closed Lost | H16: No | J16: 45936 | K16: 45860 | M16: Consulting | N16: Portal | O16: Madhav Mitruka | Y16: 2025-07-02 | Z16: https://app.hubspot.com/contacts/243046792/record/0-3/110968803016
A17: 16 | B17: 127424133880 | C17: 5400028271 | D17: State of South Carolina - STC Dynamics Managed Service Provider | E17: State of South Carolina | F17: South Carolina | G17: Closed Won | H17: No | J17: 45971 | K17: 45860 | M17: Managed Services (MSP);Staff Augmentation | N17: Email | O17: Jyothsna Nanda kishore | S17: 2025-11-06 | U17: 45967 | Y17: 2025-07-22 | Z17: https://app.hubspot.com/contacts/243046792/record/0-3/127424133880 | AA17: Yes
A18: 17 | B18: 114864544502 | D18: University System of New Hampshire - Workday Related Staff Augmentation and Project Work | E18: University System of New Hampshire | F18: New Hampshire | G18: Closed Won | H18: No | J18: 45981 | K18: 45861 | M18: Staff Augmentation | N18: Portal | O18: Madhav Mitruka | S18: 2025-11-20 | U18: 46009 | Y18: 2025-07-08 | Z18: https://app.hubspot.com/contacts/243046792/record/0-3/114864544502
A19: 18 | B19: 114864633585 | D19: IT Services | E19: Midway City Corporation | F19: Utah | G19: Closed Lost | H19: No | J19: 45943 | K19: 45866 | L19: 130560 | N19: Email | O19: Madhav Mitruka | Y19: 2025-07-09 | Z19: https://app.hubspot.com/contacts/243046792/record/0-3/114864633585
A20: 19 | B20: 114864655035 | D20: IT CYBERSECURITY MANAGED SERVICES | E20: Clark Township | F20: New Jersey | G20: Closed Lost | H20: No | J20: 45943 | K20: 45867 | L20: 444440 | M20: Managed Services (MSP) | N20: Offline | O20: Madhav Mitruka | Y20: 2025-07-09 | Z20: https://app.hubspot.com/contacts/243046792/record/0-3/114864655035
A21: 20 | B21: 115653873387 | D21: Implementation Services for Microsoft Power Platform Solution for NYS Department of Health’s Temporary Healthcare Staffing Agency Registration System | E21: New York State Department of Health | F21: New York | G21: Closed Lost | H21: No | J21: 45936 | K21: 45868 | L21: 111000 | M21: Platform Implementation (ERP, CRMs) | N21: Email | O21: Madhav Mitruka | Y21: 2025-07-07 | Z21: https://app.hubspot.com/contacts/243046792/record/0-3/115653873387
A22: 21 | B22: 134586521300 | D22: SMUD.org Software and Technical Infrastructure Upgrade | E22: Sacramento Municipal Utility District | F22: California | G22: Closed Lost | H22: No | J22: 45975 | K22: 45868 | O22: Jyothsna Nanda kishore | Y22: 2025-07-31 | Z22: https://app.hubspot.com/contacts/243046792/record/0-3/134586521300
A23: 22 | B23: 110968802000 | C23: 201-2025-1000-1 | D23: School Data Migration | E23: North Dakota Department of Public Instruction | F23: North Dakota | G23: Terminated | H23: No | J23: 46154 | K23: 45868 | L23: 193000 | M23: Modernization / Migration | N23: Portal | O23: Arshdeep Kaur | Y23: 2025-07-02 | Z23: https://app.hubspot.com/contacts/243046792/record/0-3/110968802000 | AA23: Yes
A24: 23 | B24: 121105455817 | D24: MSSP | E24: City of Aurora | F24: Illinois | G24: Closed Lost | H24: No | J24: 45947 | K24: 45875 | L24: 4000000 | N24: Portal | O24: Madhav Mitruka | Y24: 2025-07-15 | Z24: https://app.hubspot.com/contacts/243046792/record/0-3/121105455817
A25: 24 | B25: 123259080428 | C25: 26-08-09 | D25: [Destroyed] Cybersecurity Pilot - Privileged Access Management (Pam) | E25: Weslaco ISD | F25: Texas | G25: Closed Lost | H25: No | J25: 45964 | K25: 45876 | L25: 34800 | M25: Managed Services (MSP) | N25: Portal | O25: Jyothsna Nanda kishore | Y25: 2025-07-18 | Z25: https://app.hubspot.com/contacts/243046792/record/0-3/123259080428
A26: 25 | B26: 122926380739 | D26: Clark County- Managed IT Services | E26: Clark County Sheriff's Office | F26: Ohio | G26: Closed Lost | H26: No | J26: 45975 | K26: 45876 | O26: Jyothsna Nanda kishore | Y26: 2025-07-18 | Z26: https://app.hubspot.com/contacts/243046792/record/0-3/122926380739
A27: 26 | B27: 114864545523 | C27: 25-003QP | D27: 25-003QP-Accela Business Systems Analysis | E27: City of Seattle | F27: Washington | G27: Closed Lost | H27: Yes | I27: Interview | J27: 45999 | K27: 45876 | L27: 477043 | M27: Consulting;Staff Augmentation | N27: Portal | O27: Ashutosh Chauhan | P27: Interview Scheduled | Q27: 2025-11-05 | Y27: 2025-07-08 | Z27: https://app.hubspot.com/contacts/243046792/record/0-3/114864545523
A28: 27 | B28: 120592685811 | C28: RFQ-1001295 | D28: Iowa State University - Cybersecurity Services for Iowa Political Subdivisions | E28: Iowa State University | F28: Iowa | G28: Closed Won | H28: No | J28: 45981 | K28: 45877 | M28: Audits and Assessment | N28: Portal | O28: Jyothsna Nanda kishore | S28: 2025-11-20 | U28: 46156 | Y28: 2025-07-15 | Z28: https://app.hubspot.com/contacts/243046792/record/0-3/120592685811 | AA28: Yes
A29: 28 | B29: 132776618729 | C29: IT-26-002 | D29: IT Professional Services - Laguna Beach | E29: Laguna Beach | F29: California | G29: Closed Lost | H29: No | J29: 45943 | K29: 45880 | M29: Managed Services (MSP) | N29: Portal | O29: Madhav Mitruka | Y29: 2025-07-29 | Z29: https://app.hubspot.com/contacts/243046792/record/0-3/132776618729
A30: 29 | B30: 114864632540 | D30: LP&L Oracle Utility Systems Support and Optimization Services | E30: Lubbock Power & Light | F30: Texas | G30: Closed Lost | H30: No | J30: 45943 | K30: 45881 | L30: 288000 | N30: Portal | O30: Madhav Mitruka | Y30: 2025-07-09 | Z30: https://app.hubspot.com/contacts/243046792/record/0-3/114864632540
A31: 30 | B31: 135506178796 | C31: RFP No: 7-30-25 | D31: Virtual CISO Services, HCCC Mountain Line, New Jersey | E31: Hudson County Community College | F31: New Jersey | G31: Closed Lost | H31: No | J31: 45960 | K31: 45882 | L31: 236100 | M31: Managed Services (MSP) | N31: Offline | O31: Jyothsna Nanda kishore | Y31: 2025-08-01 | Z31: https://app.hubspot.com/contacts/243046792/record/0-3/135506178796
A32: 31 | B32: 137470794434 | C32: BD-26-1274-TAOFF-TAOFF-119023 | D32: RFP - IT Support Services | E32: TOWN OF GRAFTON, OFFICE OF THE TOWN ADMINISTRATOR | F32: Massachusetts | G32: Closed Lost | H32: No | J32: 45975 | K32: 45885 | O32: Jyothsna Nanda kishore | Y32: 2025-08-06 | Z32: https://app.hubspot.com/contacts/243046792/record/0-3/137470794434
A33: 32 | B33: 129524913852 | C33: 2124952 | D33: Broadcom CA ESP dSeries Workload Automation Migration | E33: New York State Office of the State Comptroller | F33: New York | G33: Closed Lost | H33: Yes | I33: Interview | J33: 46182 | K33: 45887 | L33: 126200 | M33: Modernization / Migration | N33: Email | O33: Madhav Mitruka | P33: Interview Scheduled | Q33: 2025-10-23 | Y33: 2025-07-28 | Z33: https://app.hubspot.com/contacts/243046792/record/0-3/129524913852 | AA33: Yes
A34: 33 | B34: 122926374597 | D34: Managed IT Services | E34: City of Sultan | F34: Washington | G34: Closed Lost | H34: Yes | I34: Interview | J34: 45999 | K34: 45889 | M34: Managed Services (MSP) | O34: Madhav Mitruka | P34: Interview Scheduled | Q34: 2025-09-17 | Y34: 2025-07-18 | Z34: https://app.hubspot.com/contacts/243046792/record/0-3/122926374597
A35: 34 | B35: 137207253716 | C35: SRC0000032957 | D35: Peoplesoft Managed Services | E35: Ohio Department of Taxation | F35: Ohio | G35: Closed Lost | H35: No | J35: 45960 | K35: 45890 | L35: 47400 | M35: Managed Services (MSP) | N35: Portal | O35: Madhav Mitruka | Y35: 2025-08-06 | Z35: https://app.hubspot.com/contacts/243046792/record/0-3/137207253716
A36: 35 | B36: 142119196407 | D36: Information Technology Consulting and Support| Tahoe | E36: Tahoe Transportation District | F36: Nevada | G36: Closed Lost | H36: No | J36: 45936 | K36: 45891 | L36: 318549 | M36: Managed Services (MSP) | O36: Madhav Mitruka | Y36: 2025-08-14 | Z36: https://app.hubspot.com/contacts/243046792/record/0-3/142119196407
A37: 36 | B37: 137470794439 | C37: ITS-001-26 | D37: HIPAA Privacy & Security Assessment | E37: Boston Public Health Commission | F37: Massachusetts | G37: Closed Lost | H37: No | J37: 45972 | K37: 45891 | L37: 56300 | M37: Consulting | N37: Email | O37: Jyothsna Nanda kishore | Y37: 2025-08-06 | Z37: https://app.hubspot.com/contacts/243046792/record/0-3/137470794439
A38: 37 | B38: 141008904946 | C38: AD-25-RFP-2027 | D38: IT Outsourced Help Desk and Infrastructure | E38: Housing Authority of the City of New Haven d/b/a Elm City Communities (ECC) | F38: Connecticut | G38: Closed Lost | H38: Yes | I38: Interview | J38: 45979 | K38: 45891 | L38: 3200000 | N38: Portal | O38: Madhav Mitruka | P38: Interview Scheduled | Q38: 2025-10-16 | Y38: 2025-08-13 | Z38: https://app.hubspot.com/contacts/243046792/record/0-3/141008904946
A39: 38 | B39: 135506180801 | C39: RFP 25-HR-001 | D39: HR Civil Service Records Management System | E39: County of Oswego | F39: New York | G39: Closed Lost | H39: No | J39: 45944 | K39: 45896 | L39: 320760 | N39: Portal | O39: Jyothsna Nanda kishore | Y39: 2025-08-01 | Z39: https://app.hubspot.com/contacts/243046792/record/0-3/135506180801
A40: 39 | B40: 137815198453 | C40: RFP No. FIN0825-001 | D40: Municipal Water District of Orange County (MWDOC) Enterprise Planning Resource (ERP) System Architecture and Configuration (RFP No. FIN0825-001) | E40: Municipal Water District of Orange County (MWDOC) | F40: California | G40: Closed Won | H40: Yes | I40: Interview | J40: 45936 | K40: 45905 | L40: 90000 | M40: Platform Implementation (ERP, CRMs) | N40: Email | O40: Madhav Mitruka | P40: Interview Scheduled | Q40: 2025-09-17 | S40: 2025-10-13 | U40: 45972 | V40: In Process | Y40: 2025-08-06 | Z40: https://app.hubspot.com/contacts/243046792/record/0-3/137815198453 | AA40: Yes
...

Sheet Awards
A1: S.No. | B1: HubSpot ID | C1: RFP Number | D1: Deal Name | E1: Agency | F1: Agency State | G1: Stage | H1: Interview Flag | I1: Interview Subcategory | J1: Bid Closing Date | K1: Submission Date | L1: Amount ($) | M1: Service Category | N1: Submission Mode | O1: Owner | P1: Interview Type | Q1: Interview Date | R1: BAFO Date | S1: Intent to Award Date | T1: Tentatively Awarded Date | U1: Awarded Date | V1: Award Status | W1: Won Reason | X1: Lost Reason | Y1: Created Date | Z1: HubSpot Link | AA1: Delivery Required
A2: 1 | B2: 126592758469 | C2: (RFQ) #T000599 | D2: New York Department of Financial Services - Data Governance Training | E2: New York Department of Financial Services | F2: New York | G2: Closed Won | H2: No | J2: 45526 | K2: 45527 | L2: 5800 | M2: Training | N2: Email | O2: Jyothsna Nanda kishore | S2: 2024-11-07 | U2: 45663 | V2: In Process | Y2: 2025-07-21 | Z2: https://app.hubspot.com/contacts/243046792/record/0-3/126592758469 | AA2: Yes
A3: 2 | B3: 127482765027 | C3: SW1025 | D3: Office of Management & Enterprise Services - IT Staffing | E3: Office of Management & Enterprise Services | F3: Oklahoma | G3: Closed Won | H3: No | J3: 45596 | K3: 45596 | M3: Staff Augmentation | N3: Portal | O3: Jyothsna Nanda kishore | Y3: 2025-07-23 | Z3: https://app.hubspot.com/contacts/243046792/record/0-3/127482765027 | AA3: No
A4: 3 | B4: 116521161421 | D4: NACCHO - CUSTOM JAVASCRIPT PROGRAMMING | E4: NACCHO | F4: D.C. | G4: Closed Won | H4: No | J4: 45614 | K4: 45614 | L4: 9225 | M4: Consulting | N4: Email | O4: Jyothsna Nanda kishore | S4: 2024-12-13 | U4: 45346 | Y4: 2025-07-09 | Z4: https://app.hubspot.com/contacts/243046792/record/0-3/116521161421 | AA4: Yes
A5: 4 | B5: 127482767062 | C5: 2024-013 | D5: Marin Housing Authority- Managed IT Services, CIO and Cybersecurity Services | E5: Marin Housing Authority | F5: California | G5: Closed Won | H5: No | J5: 45632 | K5: 45632 | L5: 838500 | M5: Managed Services (MSP) | N5: Portal | O5: Jyothsna Nanda kishore | S5: 2024-12-26 | U5: 45661 | Y5: 2025-07-23 | Z5: https://app.hubspot.com/contacts/243046792/record/0-3/127482767062 | AA5: Yes
A6: 5 | B6: 126590238401 | C6: RFQ #01-25 | D6: Macomb County - Microsoft 365 Migration | E6: Macomb County | F6: Michigan | G6: Closed Won | H6: Yes | I6: Interview | J6: 45701 | K6: 45670 | L6: 404900 | M6: Modernization / Migration | N6: Offline | O6: Jyothsna Nanda kishore | P6: Interview Scheduled | Q6: 2025-03-07 | S6: 2025-04-23 | U6: 45812 | V6: In Process | Y6: 2025-07-21 | Z6: https://app.hubspot.com/contacts/243046792/record/0-3/126590238401 | AA6: Yes
A7: 6 | B7: 127701416677 | C7: RFP- 282503 | D7: Arizona State University - Digital Accessibility Services | E7: Arizona State University | F7: Arizona | G7: Closed Won | H7: No | J7: 45679 | K7: 45679 | M7: Consulting;Training;Audits and Assessment | N7: Portal | O7: Jyothsna Nanda kishore | S7: 2025-07-16 | U7: 45912 | Y7: 2025-07-23 | Z7: https://app.hubspot.com/contacts/243046792/record/0-3/127701416677 | AA7: No
A8: 7 | B8: 127482766020 | D8: San Mateo County - Contingency Health IT Staffing | E8: County of San Mateo | F8: California | G8: Closed Won | H8: No | J8: 45719 | K8: 45716 | M8: Staff Augmentation | N8: Portal | O8: Arshdeep Kaur | S8: 2025-03-05 | U8: 45797 | Y8: 2025-07-23 | Z8: https://app.hubspot.com/contacts/243046792/record/0-3/127482766020 | AA8: No
A9: 8 | B9: 127685792505 | C9: EVT00010112 | D9: Kansas Dept. of Administration - Temporary Staffing Services | E9: Kansas Department of Administration | F9: Kansas | G9: Closed Won | H9: No | J9: 45737 | K9: 45737 | M9: Staff Augmentation | O9: Arshdeep Kaur | S9: 2025-04-23 | U9: 45772 | Y9: 2025-07-23 | Z9: https://app.hubspot.com/contacts/243046792/record/0-3/127685792505 | AA9: No
A10: 9 | B10: 127690112742 | D10: Illinois Department of Public Health- Data Literacy Training | E10: Illinois Department of Public Health | F10: Illinios | G10: Closed Won | H10: No | J10: 45743 | K10: 45743 | L10: 18499 | M10: Training | N10: Portal | O10: Jyothsna Nanda kishore | S10: 2025-05-05 | U10: 45868 | V10: In Process | Y10: 2025-07-23 | Z10: https://app.hubspot.com/contacts/243046792/record/0-3/127690112742 | AA10: Yes
A11: 10 | B11: 127482769082 | D11: Ohio Department of Natural Resources- H2O PROJECT MANAGEMENTTASK TACKING TOOLENHANCEMENTS-SALESFORCE DEVELOPER | E11: Ohio Department of Natural Resources | F11: Ohio | G11: Closed Won | H11: No | J11: 45747 | K11: 45747 | L11: 11275 | M11: Platform Implementation (ERP, CRMs) | N11: Portal | O11: Jyothsna Nanda kishore | S11: 2025-04-03 | U11: 45764 | V11: Completed | Y11: 2025-07-23 | Z11: https://app.hubspot.com/contacts/243046792/record/0-3/127482769082 | AA11: Yes
A12: 11 | B12: 114864632563 | C12: IT1638-25 | D12: Marion County - Oracle Support Services | E12: Marion County | F12: Oregon | G12: Closed Won | H12: No | J12: 45750 | K12: 45750 | L12: 100000 | M12: Support & Maintenance | N12: Portal | O12: Jyothsna Nanda kishore | S12: 2025-05-19 | U12: 45819 | V12: In Process | Y12: 2025-07-09 | Z12: https://app.hubspot.com/contacts/243046792/record/0-3/114864632563 | AA12: Yes
A13: 12 | B13: 127482750660 | D13: Metropolitan Water District of Southern California - ON-CALL INFORMATION TECHNOLOGY (IT) QUALITY ASSURANCE AND CONTROL, PROJECT MANAGEMENT, AND BUSINESS ANALYSIS SUPPORT SERVICES (RFQ-MN-1395) | E13: Metropolitan Water District of Southern California | F13: California | G13: Closed Won | H13: No | J13: 45755 | K13: 45755 | M13: Staff Augmentation | N13: Portal | O13: Madhav Mitruka | S13: 2025-07-22 | U13: 45860 | Y13: 2025-07-23 | Z13: https://app.hubspot.com/contacts/243046792/record/0-3/127482750660 | AA13: No
A14: 13 | B14: 126600317675 | C14: RFP S24262 | D14: SCVTA - Employee Application | E14: Santa Clara Valley Transportation Authority | F14: California | G14: Closed Won | H14: Yes | I14: Interview | J14: 45729 | K14: 45761 | L14: 140000 | M14: Custom development | N14: Portal | O14: Jyothsna Nanda kishore | P14: Interview Scheduled | Q14: 2025-05-08 | S14: 2025-06-26 | U14: 45902 | V14: In Process | Y14: 2025-07-21 | Z14: https://app.hubspot.com/contacts/243046792/record/0-3/126600317675 | AA14: Yes
A15: 14 | B15: 126595998395 | C15: DOR RFP 24/25-59 | D15: Florida Department of Revenue - SAP License Analysis | E15: Florida Department of Revenue | F15: Florida | G15: Closed Won | H15: No | J15: 45761 | K15: 45761 | L15: 58800 | M15: Audits and Assessment | N15: Offline | O15: Jyothsna Nanda kishore | S15: 2025-05-22 | U15: 45817 | V15: In Process | Y15: 2025-07-21 | Z15: https://app.hubspot.com/contacts/243046792/record/0-3/126595998395 | AA15: Yes
A16: 15 | B16: 235860602564 | C16: RFQ-AR-1398 | D16: Metropolitan Water District of Southern California - On-Call Information Technology Cybersecurity Services | E16: Metropolitan Water District of Southern California | F16: California | G16: Closed Won | H16: No | J16: 45999 | K16: 45771 | M16: Managed Services (MSP) | N16: Portal | O16: Madhav Mitruka | S16: 2025-12-02 | U16: 45993 | Y16: 2025-12-08 | Z16: https://app.hubspot.com/contacts/243046792/record/0-3/235860602564
A17: 16 | B17: 186570653428 | C17: 405 24R0019168C | D17: Texas Department of Public Safety - Cherwell Professional Services | E17: Texas Department of Public Safety | F17: Texas | G17: Closed Won | H17: No | J17: 45791 | K17: 45790 | L17: 148500 | M17: Managed Services (MSP) | N17: Email | O17: Ashley Lamaniya | S17: 2025-10-09 | U17: 45947 | Y17: 2025-10-13 | Z17: https://app.hubspot.com/contacts/243046792/record/0-3/186570653428 | AA17: Yes
A18: 17 | B18: 127482765035 | C18: RFP NO. NC- 2025-14 | D18: Fresno County Superintendent of Schools - Computer Maintenance & Technology Support Services | E18: FRESNO COUNTY SUPERINTENDENT OF SCHOOLS | F18: California | G18: Closed Won | H18: No | J18: 45796 | K18: 45796 | L18: 500000 | M18: Consulting;Support & Maintenance | N18: Email | O18: Arshdeep Kaur | S18: 2025-06-13 | U18: 45968 | V18: In Process | Y18: 2025-07-23 | Z18: https://app.hubspot.com/contacts/243046792/record/0-3/127482765035 | AA18: No
A19: 18 | B19: 108072562388 | D19: Madison Metropolitan Sewerage District - IT Augmentation Partner (SOW 1) | E19: Madison Metropolitan Sewerage District | F19: Wisconsin | G19: Closed Won | H19: Yes | I19: Interview | J19: 45903 | K19: 45801 | L19: 1081349.5 | M19: Managed Services (MSP) | O19: Madhav Mitruka | P19: Interview Scheduled | Q19: 2025-07-28 | S19: 2025-08-14 | U19: 45918 | V19: In Process | Y19: 2025-06-25 | Z19: https://app.hubspot.com/contacts/243046792/record/0-3/108072562388 | AA19: Yes
A20: 19 | B20: 127743477490 | D20: EPIC 6- RFP 21.25 Technology Solutions & Services | E20: Region 6 Education Service Center | F20: Texas | G20: Closed Won | H20: No | J20: 46142 | K20: 45807 | M20: Staff Augmentation | N20: Portal | O20: Jyothsna Nanda kishore | S20: 2025-06-16 | U20: 45831 | Y20: 2025-07-23 | Z20: https://app.hubspot.com/contacts/243046792/record/0-3/127743477490 | AA20: No
A21: 20 | B21: 135608301264 | C21: RFP-3578 | D21: Port Houston - Managed Network Operations Center Services | E21: Port Houston | F21: Texas | G21: Closed Won | H21: Yes | I21: Interview | J21: 45917 | K21: 45819 | L21: 1183000 | M21: Managed Services (MSP) | O21: Madhav Mitruka | P21: Interview Scheduled | Q21: 2025-07-23 | S21: 2025-09-23 | U21: 45967 | V21: In Process | Y21: 2025-08-01 | Z21: https://app.hubspot.com/contacts/243046792/record/0-3/135608301264 | AA21: Yes
A22: 21 | B22: 175110048474 | D22: Commonwealth of Pennsylvania - Agile ITQ Development | E22: Commonwealth of Pennsylvania | F22: Pennsylvania | G22: Closed Won | H22: No | J22: 45932 | K22: 45832 | M22: Staff Augmentation | N22: Portal | O22: Madhav Mitruka | S22: 2025-10-02 | U22: 45932 | Y22: 2025-10-02 | Z22: https://app.hubspot.com/contacts/243046792/record/0-3/175110048474 | AA22: No
A23: 22 | B23: 181172764367 | D23: Monroe County - Temporary Personnel Services for Information Technology | E23: Monroe County | F23: New York | G23: Closed Won | H23: No | J23: 45835 | K23: 45833 | M23: Platform Implementation (ERP, CRMs);Support & Maintenance | N23: Email | O23: Jyothsna Nanda kishore | S23: 2025-10-08 | U23: 45938 | Y23: 2025-10-08 | Z23: https://app.hubspot.com/contacts/243046792/record/0-3/181172764367 | AA23: Yes
A24: 23 | B24: 127677476588 | C24: 23-030 | D24: San Antonio Independent School District - Miscellaneous Consultant Services | E24: San Antonio Independent School District | F24: Texas | G24: Closed Won | H24: No | J24: 45838 | K24: 45838 | M24: Staff Augmentation | N24: Portal | O24: Jyothsna Nanda kishore | S24: 2025-07-11 | U24: 45849 | V24: In Process | Y24: 2025-07-23 | Z24: https://app.hubspot.com/contacts/243046792/record/0-3/127677476588 | AA24: No
A25: 24 | B25: 110712028891 | D25: Oregon League of Cities - STAFFING SERVICES WITH RELATED SERVICES AND SOLUTIONS | E25: Oregon League of Cities | F25: Oregon | G25: Closed Won | H25: No | J25: 46007 | K25: 45859 | M25: Staff Augmentation | N25: Portal | O25: Madhav Mitruka | S25: 2025-12-15 | U25: 46066 | Y25: 2025-07-01 | Z25: https://app.hubspot.com/contacts/243046792/record/0-3/110712028891 | AA25: Yes
A26: 25 | B26: 127424133880 | C26: 5400028271 | D26: State of South Carolina - STC Dynamics Managed Service Provider | E26: State of South Carolina | F26: South Carolina | G26: Closed Won | H26: No | J26: 45971 | K26: 45860 | M26: Managed Services (MSP);Staff Augmentation | N26: Email | O26: Jyothsna Nanda kishore | S26: 2025-11-06 | U26: 45967 | Y26: 2025-07-22 | Z26: https://app.hubspot.com/contacts/243046792/record/0-3/127424133880 | AA26: Yes
A27: 26 | B27: 114864544502 | D27: University System of New Hampshire - Workday Related Staff Augmentation and Project Work | E27: University System of New Hampshire | F27: New Hampshire | G27: Closed Won | H27: No | J27: 45981 | K27: 45861 | M27: Staff Augmentation | N27: Portal | O27: Madhav Mitruka | S27: 2025-11-20 | U27: 46009 | Y27: 2025-07-08 | Z27: https://app.hubspot.com/contacts/243046792/record/0-3/114864544502
A28: 27 | B28: 134329484998 | D28: Collier County - OPENCollier MPO WordPress Website Maintenance & Hosting | E28: Collier County | F28: Florida | G28: Closed Won | H28: No | J28: 45924 | K28: 45867 | L28: 3990 | M28: Support & Maintenance | N28: Portal | O28: Madhav Mitruka | S28: 2025-09-24 | U28: 45924 | Y28: 2025-07-29 | Z28: https://app.hubspot.com/contacts/243046792/record/0-3/134329484998
A29: 29 | B29: 120592685811 | C29: RFQ-1001295 | D29: Iowa State University - Cybersecurity Services for Iowa Political Subdivisions | E29: Iowa State University | F29: Iowa | G29: Closed Won | H29: No | J29: 45981 | K29: 45877 | M29: Audits and Assessment | N29: Portal | O29: Jyothsna Nanda kishore | S29: 2025-11-20 | U29: 46156 | Y29: 2025-07-15 | Z29: https://app.hubspot.com/contacts/243046792/record/0-3/120592685811 | AA29: Yes
A30: 32 | B30: 126587718330 | D30: Alachua County Library District - E-Rate Cybersecurity Pilot Program - Next Generation Firewall | E30: Alachua County Library District | F30: Florida | G30: Closed Won | H30: No | J30: 45905 | K30: 45890 | L30: 73000 | M30: Consulting | N30: Portal | O30: Yashaswini Gautam | S30: 2025-09-05 | U30: 46132 | Y30: 2025-07-21 | Z30: https://app.hubspot.com/contacts/243046792/record/0-3/126587718330
A31: 33 | B31: 144659629780 | C31: 02805095 | D31: St. Johns County - Veeam VBR Enterprise Basic Maintenance License Renew | E31: St. Johns County | F31: Florida | G31: Closed Won | H31: No | J31: 45910 | K31: 45891 | L31: 15712 | M31: Reseller | N31: Email | O31: Madhav Mitruka | S31: 2025-09-22 | U31: 45922 | Y31: 2025-08-22 | Z31: https://app.hubspot.com/contacts/243046792/record/0-3/144659629780
A32: 34 | B32: 137815198453 | C32: RFP No. FIN0825-001 | D32: Municipal Water District of Orange County (MWDOC) Enterprise Planning Resource (ERP) System Architecture and Configuration (RFP No. FIN0825-001) | E32: Municipal Water District of Orange County (MWDOC) | F32: California | G32: Closed Won | H32: Yes | I32: Interview | J32: 45936 | K32: 45905 | L32: 90000 | M32: Platform Implementation (ERP, CRMs) | N32: Email | O32: Madhav Mitruka | P32: Interview Scheduled | Q32: 2025-09-17 | S32: 2025-10-13 | U32: 45972 | V32: In Process | Y32: 2025-08-06 | Z32: https://app.hubspot.com/contacts/243046792/record/0-3/137815198453 | AA32: Yes
A33: 35 | B33: 145845264086 | D33: City of Olmos Park - Information Technology Services | E33: City of Olmos Park | F33: Texas | G33: Closed Won | H33: No | J33: 45918 | K33: 45911 | L33: 184400 | M33: Managed Services (MSP) | N33: Offline | O33: Arshdeep Kaur | S33: 2025-09-18 | U33: 45946 | V33: In Process | Y33: 2025-08-26 | Z33: https://app.hubspot.com/contacts/243046792/record/0-3/145845264086 | AA33: Yes
A34: 36 | B34: 134489494217 | D34: Florida Department of Management Services - Prequalification for Information Technology Staff Augmentation Services (Supplemental) 2025 | E34: Florida Department of Management Services | F34: Florida | G34: Closed Won | H34: No | J34: 45932 | K34: 45916 | M34: Staff Augmentation | N34: Portal | O34: Madhav Mitruka | S34: 2025-09-16 | U34: 46049 | Y34: 2025-07-30 | Z34: https://app.hubspot.com/contacts/243046792/record/0-3/134489494217 | AA34: No
A35: 37 | B35: 144653136611 | D35: Western Municipal Water District - Data Solution Design, Build & Implementation, Western Municipal Water District (Western Water) | E35: Western Municipal Water District | F35: California | G35: Closed Won | H35: No | J35: 46009 | K35: 45918 | L35: 143460 | M35: Modernization / Migration | N35: Portal | O35: Jyothsna Nanda kishore | S35: 2025-11-18 | U35: 45973 | V35: In Process | Y35: 2025-08-22 | Z35: https://app.hubspot.com/contacts/243046792/record/0-3/144653136611 | AA35: Yes
A36: 38 | B36: 159541459657 | C36: WSD001 | D36: County of Los Angeles Department of Public Works - Microsoft Power Platform Training | E36: County of Los Angeles Department of Public Works | F36: California | G36: Closed Won | H36: No | J36: 46114 | K36: 45925 | L36: 12000 | M36: Training | N36: Email | O36: Jyothsna Nanda kishore | S36: 2026-04-02 | U36: 46113 | Y36: 2025-09-12 | Z36: https://app.hubspot.com/contacts/243046792/record/0-3/159541459657 | AA36: Yes
A37: 39 | B37: 158113558258 | D37: TRIMET - Data Center Assessment and Risk Mitigation Strategy | E37: Tri-County Metropolitan Transportation District of Oregon | F37: Oregon | G37: Closed Won | H37: Yes | I37: BAFO | J37: 46143 | K37: 45929 | L37: 20893 | M37: Audits and Assessment | N37: Portal | O37: Ashutosh Chauhan | P37: BAFO | R37: 2025-10-15 | S37: 2025-10-20 | U37: 45953 | Y37: 2025-09-10 | Z37: https://app.hubspot.com/contacts/243046792/record/0-3/158113558258 | AA37: Yes
A38: 40 | B38: 126595998432 | C38: RFP-554-2025-0052-0-2025/AH | D38: Raleigh Durham Airport Authority (NC) - SharePoint Consultant | E38: Raleigh Durham Airport Authority [NC] | F38: North Carolina | G38: Intent to Award | H38: No | J38: 46052 | K38: 45932 | L38: 18830 | M38: Consulting | N38: Portal | O38: Madhav Mitruka | S38: 46052 | Y38: 2025-07-21 | Z38: https://app.hubspot.com/contacts/243046792/record/0-3/126595998432
A39: 41 | B39: 161660341982 | D39: Greene County - PROFESSIONAL CONSULTANT SERVICES | E39: Greene County | F39: New York | G39: Closed Won | H39: No | J39: 46143 | K39: 45932 | M39: Staff Augmentation | N39: Offline | O39: Arshdeep Kaur | S39: 2025-12-09 | U39: 46093 | Y39: 2025-09-17 | Z39: https://app.hubspot.com/contacts/243046792/record/0-3/161660341982 | AA39: No
A40: 42 | B40: 158113559231 | D40: City of San Carlos - Legacy File Server Migration to SharePoint Modernization | E40: City of San Carlos | F40: California | G40: Closed Won | H40: Yes | I40: Interview | J40: 46149 | K40: 45936 | L40: 98000 | M40: Modernization / Migration | N40: Email | O40: Abhishek Zalani | P40: Interview Scheduled | Q40: 2025-12-10 | S40: 2026-01-01 | U40: 46031 | Y40: 2025-09-10 | Z40: https://app.hubspot.com/contacts/243046792/record/0-3/158113559231
...
